<?xml version="1.0"?>
<robot name="barista_robot">
    <!-- White Material -->
    <material name="white">
        <color rgba="1 1 1 1"/>
    </material>
    <!-- Black Material -->
    <material name="black">
        <color rgba="0 0 0 1"/>
    </material>
    <!-- Reference Frame-->
    <link name="base_link"/>
    <!-- Chassis -->
    <link name="chassis">
        <visual>
            <origin rpy="0 0 0" xyz="0 0 0"/>
            <geometry>
                <mesh filename="package://barista_robot_description/meshes/chassis.dae" scale="1 1 1"/>
            </geometry>
        </visual>
        <inertial>
            <mass value="12"/>
            <origin rpy="0 0 0" xyz="0 0 0"/>
            <inertia ixx="0.119077" ixy="0" ixz="0" iyy="0.119077" iyz="0" izz="0.190104"/>
        </inertial>
        <collision>
            <origin rpy="0 0 0" xyz="0 0 0"/>
            <geometry>
                <cylinder radius="0.178" length="0.155"/>
            </geometry>
        </collision>
    </link>
    <!-- Rod A -->
    <link name="rod_a">
        <visual>
            <origin rpy="0 0 0" xyz="0 0 0"/>
            <geometry>
                <cylinder radius="0.01" length="0.22"/>
            </geometry>
            <material name="white"/>
        </visual>
        <inertial>
            <mass value="0.25"/>
            <origin rpy="0 0 0" xyz="0 0 0"/>
            <inertia ixx="0.001015" ixy="0" ixz="0" iyy="0.001015" iyz="0" izz="0.000013"/>
        </inertial>
        <collision>
            <origin rpy="0 0 0" xyz="0 0 0"/>
            <geometry>
               <cylinder radius="0.01" length="0.22"/>
            </geometry>
        </collision>
    </link>
    <gazebo reference="rod_a">
        <material>Gazebo/White</material>
    </gazebo>
    <!-- Rod B -->
    <link name="rod_b">
        <visual>
            <origin rpy="0 0 0" xyz="0 0 0"/>
            <geometry>
                <cylinder radius="0.01" length="0.22"/>
            </geometry>
            <material name="white"/>
        </visual>
        <inertial>
            <mass value="0.25"/>
            <origin rpy="0 0 0" xyz="0 0 0"/>
            <inertia ixx="0.001015" ixy="0" ixz="0" iyy="0.001015" iyz="0" izz="0.000013"/>
        </inertial>
        <collision>
            <origin rpy="0 0 0" xyz="0 0 0"/>
            <geometry>
                <cylinder radius="0.01" length="0.22"/>
            </geometry>
        </collision>
    </link>
    <gazebo reference="rod_b">
        <material>Gazebo/White</material>
    </gazebo>
    <!-- Rod C -->
    <link name="rod_c">
        <visual>
            <origin rpy="0 0 0" xyz="0 0 0"/>
            <geometry>
                <cylinder radius="0.01" length="0.22"/>
            </geometry>
            <material name="white"/>
        </visual>
        <inertial>
            <mass value="0.25"/>
            <origin rpy="0 0 0" xyz="0 0 0"/>
            <inertia ixx="0.001015" ixy="0" ixz="0" iyy="0.001015" iyz="0" izz="0.000013"/>
        </inertial>
        <collision>
            <origin rpy="0 0 0" xyz="0 0 0"/>
            <geometry>
                <cylinder radius="0.01" length="0.22"/>
            </geometry>
        </collision>
    </link>
    <gazebo reference="rod_c">
        <material>Gazebo/White</material>
    </gazebo>
    <!-- Rod D -->
    <link name="rod_d">
        <visual>
            <origin rpy="0 0 0" xyz="0 0 0"/>
            <geometry>
                <cylinder radius="0.01" length="0.22"/>
            </geometry>
            <material name="white"/>
        </visual>
        <inertial>
            <mass value="0.25"/>
            <origin rpy="0 0 0" xyz="0 0 0"/>
            <inertia ixx="0.001015" ixy="0" ixz="0" iyy="0.001015" iyz="0" izz="0.000013"/>
        </inertial>
        <collision>
            <origin rpy="0 0 0" xyz="0 0 0"/>
            <geometry>
                <cylinder radius="0.01" length="0.22"/>
            </geometry>
        </collision>
    </link>
    <gazebo reference="rod_d">
        <material>Gazebo/White</material>
    </gazebo>
    <!-- Cup Holder -->
    <link name="cup_holder">
        <visual>
            <origin rpy="0 0 0" xyz="0 0 0"/>
            <geometry>
                <mesh filename="package://barista_robot_description/meshes/cup_holder.dae" scale="1 1 1"/>
            </geometry>
        </visual>
        <inertial>
            <mass value="6"/>
            <origin rpy="0 0 0" xyz="0 0 0"/>
            <inertia ixx="0.042450" ixy="0" ixz="0" iyy="0.042450" iyz="0" izz="0.076800"/>
        </inertial>
        <collision>
            <origin rpy="0 0 0" xyz="0 0 0"/>
            <geometry>
                <cylinder radius="0.160" length="0.090"/>
            </geometry>
        </collision>
    </link>
    <!-- Left Wheel -->
    <link name="left_wheel">
        <visual>
            <origin rpy="1.570796 0 0" xyz="0 0 0"/>
            <geometry>
                <cylinder radius="0.020" length="0.040"/>
            </geometry>
            <material name="black"/>
        </visual>
        <inertial>
            <mass value="0.25"/>
            <origin rpy="1.570796 0 0" xyz="0 0 0"/>
            <inertia ixx="0.000058" ixy="0" ixz="0" iyy="0.000058" iyz="0" izz="0.000050"/>
        </inertial>
        <collision>
            <origin rpy="1.570796 0 0" xyz="0 0 0"/>
            <geometry>
                <cylinder radius="0.020" length="0.040"/>
            </geometry>
        </collision>
    </link>
    <gazebo reference="left_wheel">
        <kp>1e6</kp>
        <kd>10</kd>
        <mu1>10.0</mu1>
        <mu2>10.0</mu2>
        <material>Gazebo/Black</material>
    </gazebo>
    <!-- Right Wheel -->
    <link name="right_wheel">
        <visual>
            <origin rpy="1.570796 0 0" xyz="0 0 0"/>
            <geometry>
                <cylinder radius="0.020" length="0.040"/>
            </geometry>
            <material name="black"/>
        </visual>
        <inertial>
            <mass value="0.25"/>
            <origin rpy="1.570796 0 0" xyz="0 0 0"/>
            <inertia ixx="0.000058" ixy="0" ixz="0" iyy="0.000058" iyz="0" izz="0.000050"/>
        </inertial>
        <collision>
            <origin rpy="1.570796 0 0" xyz="0 0 0"/>
            <geometry>
                <cylinder radius="0.020" length="0.040"/>
            </geometry>
        </collision>
    </link>
    <gazebo reference="right_wheel">
        <kp>1e6</kp>
        <kd>10</kd>
        <mu1>10.0</mu1>
        <mu2>10.0</mu2>
        <material>Gazebo/Black</material>
    </gazebo>
    <!-- Front Caster -->
    <link name="front_caster">
        <visual>
            <origin rpy="0 0 0" xyz="0 0 0"/>
            <geometry>
                <sphere radius="0.020"/>
            </geometry>
            <material name="black"/>
        </visual>
        <inertial>
            <mass value="0.25"/>
            <origin rpy="0 0 0" xyz="0 0 0"/>
            <inertia ixx="0.000040" ixy="0" ixz="0" iyy="0.000040" iyz="0" izz="0.000040"/>
        </inertial>
        <collision>
            <origin rpy="0 0 0" xyz="0 0 0"/>
            <geometry>
                <sphere radius="0.020"/>
            </geometry>
        </collision>
    </link>
    <gazebo reference="front_caster">
        <kp>1e6</kp>
        <kd>10</kd>
        <mu1>0.0</mu1>
        <mu2>0.0</mu2>
        <material>Gazebo/Black</material>
    </gazebo>
    <!-- Back Caster -->
    <link name="back_caster">
        <visual>
            <origin rpy="0 0 0" xyz="0 0 0" />
            <geometry>
                <sphere radius="0.020"/>
            </geometry>
            <material name="black"/>
        </visual>
        <inertial>
            <mass value="0.25"/>
            <origin rpy="0 0 0" xyz="0 0 0"/>
            <inertia ixx="0.000040" ixy="0" ixz="0" iyy="0.000040" iyz="0" izz="0.000040"/>
        </inertial>
        <collision>
            <origin rpy="0 0 0" xyz="0 0 0"/>
            <geometry>
                <sphere radius="0.020"/>
            </geometry>
        </collision>
    </link>
    <gazebo reference="back_caster">
        <kp>1e6</kp>
        <kd>10</kd>
        <mu1>0.0</mu1>
        <mu2>0.0</mu2>
        <material>Gazebo/Black</material>
    </gazebo>
    <!-- Laser Sensor -->
    <link name="laser_sensor">
        <visual>
            <origin rpy="0 0 0" xyz="0 0 0"/>
            <geometry>
                <mesh filename="package://barista_robot_description/meshes/hokuyo.dae" scale="1 1 1"/>
            </geometry>
        </visual>
        <inertial>
            <mass value="0.160"/>
            <origin rpy="0 0 0" xyz="0 0 0"/>
            <inertia ixx="0.000099" ixy="0" ixz="0" iyy="0.000099" iyz="0" izz="0.000066"/>
        </inertial>
        <collision>
            <origin rpy="0 0 0" xyz="0 0 0"/>
            <geometry>
                <box size="0.050 0.050 0.070"/>
            </geometry>
        </collision>
    </link>
    <!-- Laser Frame-->
    <link name="laser_frame"/>
    <!-- Reference - Chassis -->
    <joint name="reference_to_chassis" type="fixed">
        <parent link="base_link"/>
        <child link="chassis"/>
        <origin xyz="0 0 0.0975" rpy="0 0 0"/>
    </joint>
    <!-- Chassis - Rod A -->
    <joint name="chassis_to_rod_a" type="fixed">
        <parent link="chassis"/>
        <child link="rod_a"/>
        <origin xyz="0.040 0.125 0.1875" rpy="0 0 0"/>
    </joint>
    <!-- Chassis - Rod B -->
    <joint name="chassis_to_rod_b" type="fixed">
        <parent link="chassis"/>
        <child link="rod_b"/>
        <origin xyz="-0.040 0.125 0.1875" rpy="0 0 0"/>
    </joint>
    <!-- Chassis - Rod C -->
    <joint name="chassis_to_rod_c" type="fixed">
        <parent link="chassis"/>
        <child link="rod_c"/>
        <origin xyz="0.040 -0.125 0.1875" rpy="0 0 0"/>
    </joint>
    <!-- Chassis - Rod D -->
    <joint name="chassis_to_rod_d" type="fixed">
        <parent link="chassis"/>
        <child link="rod_d"/>
        <origin xyz="-0.040 -0.125 0.1875" rpy="0 0 0"/>
    </joint>
    <!-- Chassis - Cup Holder -->
    <joint name="chassis_to_cup_holder" type="fixed">
        <parent link="chassis"/>
        <child link="cup_holder"/>
        <origin xyz="0 0 0.3425" rpy="0 0 0"/>
    </joint>
    <!-- Chassis - Left Wheel -->
    <joint name="chassis_to_left_wheel" type="continuous">
        <parent link="chassis"/>
        <child link="left_wheel"/>
        <origin xyz="0 -0.145 -0.0775" rpy="0 0 0"/>
        <axis xyz="0 1 0"/>
        <limit effort="10000" velocity="1000" />
        <joint_properties damping="1.0" friction="1.0"/>
    </joint>
    <!-- Chassis - Right Wheel -->
    <joint name="chassis_to_right_wheel" type="continuous">
        <parent link="chassis"/>
        <child link="right_wheel"/>
        <origin xyz="0 0.145 -0.0775" rpy="0 0 0"/>
        <axis xyz="0 1 0"/>
        <limit effort="10000" velocity="1000" />
        <joint_properties damping="1.0" friction="1.0"/>
    </joint>
    <!-- Chassis - Front Caster -->
    <joint name="chassis_to_front_caster" type="fixed">
        <parent link="chassis"/>
        <child link="front_caster"/>
        <origin xyz="0.145 0 -0.0775" rpy="0 0 0"/>
        <joint_properties damping="1.0" friction="1.0"/>
    </joint>
    <gazebo reference="chassis_to_front_caster">
        <preserveFixedJoint>true</preserveFixedJoint>
    </gazebo>
    <!-- Chassis - Back Caster -->
    <joint name="chassis_to_back_caster" type="fixed">
        <parent link="chassis"/>
        <child link="back_caster"/>
        <origin xyz="-0.145 0 -0.0775" rpy="0 0 0"/>
        <joint_properties damping="1.0" friction="1.0"/>
    </joint>
    <gazebo reference="chassis_to_back_caster">
        <preserveFixedJoint>true</preserveFixedJoint>
    </gazebo>
    <!-- Chassis - Laser Sensor -->
    <joint name="chassis_to_laser_sensor" type="fixed">
        <parent link="chassis"/>
        <child link="laser_sensor"/>
        <origin xyz="0.130 0 0.0775" rpy="0 0 0"/>
    </joint>
    <!-- Laser Sensor - Laser Frame -->
    <joint name="laser_sensor_to_laser_frame" type="fixed">
        <parent link="laser_sensor"/>
        <child link="laser_frame"/>
        <origin xyz="0 0 0.060" rpy="0 0 0"/>
    </joint>
    <!-- Joint State Plugin -->
    <gazebo>
        <plugin name="barista_bot_joint_state" filename="libgazebo_ros_joint_state_publisher.so">
            <ros>
                <remapping>~/out:=joint_states</remapping>
            </ros>
            <update_rate>30</update_rate>
            <joint_name>chassis_to_left_wheel</joint_name>
            <joint_name>chassis_to_right_wheel</joint_name>
        </plugin>
    </gazebo>
    <!-- Differential Drive Plugin -->
    <gazebo>
        <plugin filename="libgazebo_ros_diff_drive.so" name="differential_drive_controller">
            <!-- wheels -->
            <left_joint>chassis_to_left_wheel</left_joint>
            <right_joint>chassis_to_right_wheel</right_joint>
            <!-- kinematics -->
            <wheel_separation>0.29</wheel_separation>
            <wheel_diameter>0.04</wheel_diameter>
            <!-- limits -->
            <max_wheel_torque>1.0</max_wheel_torque>
            <max_wheel_acceleration>2.0</max_wheel_acceleration>
            <!-- output -->
            <publish_odom>true</publish_odom>
            <publish_odom_tf>true</publish_odom_tf>
            <odometry_frame>odom</odometry_frame>
            <robot_base_frame>base_link</robot_base_frame>
        </plugin>
    </gazebo>
    <!-- Laser Sensor Plugin -->
    <gazebo reference="laser_frame">
        <sensor name="sensor_ray" type="ray">
            <pose>0 0 0 0 0 0</pose>
            <ray>
                <scan>
                    <horizontal>
                    <samples>200</samples>
                    <resolution>1.0</resolution>
                    <min_angle>-3.14</min_angle>
                    <max_angle>3.14</max_angle>
                    </horizontal>
                </scan>
                <range>
                    <min>0.025</min>
                    <max>5.0</max>
                </range>
            </ray>
            <always_on>true</always_on>
            <visualize>true</visualize>
            <update_rate>100.0</update_rate>
            <plugin name="laser" filename="libgazebo_ros_ray_sensor.so">
                <ros>
                    <remapping>~/out:=scan</remapping>
                </ros>
                <output_type>sensor_msgs/LaserScan</output_type>
            </plugin>
        </sensor>
    </gazebo>
</robot>
